<?xml version='1.0'?>

<robot name="robot" xmlns:xacro="http://www.ros.org/wiki/xacro">

  <xacro:include filename="$(find robot)/urdf/robot.gazebo" />

  <!-- ############### -->
  <!-- COLOR REFERENCE -->
  <!-- ############### -->

  <gazebo reference="fl_wheel">
    <material>Gazebo/Grey</material>
  </gazebo>

  <gazebo reference="fr_wheel">
    <material>Gazebo/Grey</material>
  </gazebo>

  <gazebo reference="bl_wheel">
    <material>Gazebo/Grey</material>
  </gazebo>

  <gazebo reference="br_wheel">
    <material>Gazebo/Grey</material>
  </gazebo>

  <gazebo reference="camera">
    <material>Gazebo/Green</material>
  </gazebo>

  <gazebo reference="gps_link">
    <material>Gazebo/Grey</material>
  </gazebo>

  <gazebo reference="imu_link">
    <material>Gazebo/Grey</material>
  </gazebo>

  <gazebo reference="chassis">
    <material>Gazebo/White</material>
  </gazebo>

  <gazebo reference="kinect_link">
    <material>Gazebo/Red</material>
  </gazebo>

  <gazebo reference="hokuyo">
    <material>Gazebo/Blue</material>
  </gazebo>

  <!-- <gazebo reference="ZED2_link">
    <material>Gazebo/Orange</material>
  </gazebo>  -->

  <!-- ##### -->
  <!-- LINKS -->
  <!-- ##### -->

  <!-- ROBOT FOOTPRINT -->

  <link name="robot_footprint"></link>

  <joint name="robot_footprint_joint" type="fixed">
    <origin xyz="0 0 0" rpy="0 0 0" />
    <parent link="robot_footprint"/>
    <child link="chassis" />
  </joint>

  <!-- CHASSIS -->


  <link name='chassis'>

    <inertial>
      <mass value="10"/>
      <origin xyz="0.0 0 0" rpy=" 0 0 0"/>
      <inertia
          ixx="0.375" ixy="0" ixz="0"
          iyy="1.275" iyz="0"
          izz="1.5"
      />
    </inertial>

    <collision>
      <origin xyz="0 0 0" rpy=" 0 0 0"/> 
      <geometry>
        <box size="0.6 0.51 0.2"/>
      </geometry>
    </collision>

    <visual>
      <origin xyz="0 0 0" rpy=" 0 0 0"/>
      <geometry>
       <box size="0.6 0.51 0.2"/>
      </geometry>
    </visual>

  </link>

  <!-- SUPPORT -->
  <link name='support'>

    <inertial>
      <mass value="1.0"/>
      <origin xyz="0.0 0 0" rpy=" 0 0 0"/>
      <inertia
          ixx="0.1" ixy="0" ixz="0"
          iyy="0.1" iyz="0"
          izz="0.1"
      />
    </inertial>

    <collision>
      <origin xyz="0 0 0" rpy=" 0 0 0"/> 
      <geometry>
        <box size="0.1 0.1 0.4"/>
      </geometry>
    </collision>

    <visual>
      <origin xyz="0 0 0" rpy=" 0 0 0"/>
      <geometry>
       <box size="0.1 0.1 0.4"/>
      </geometry>
    </visual>

  </link>



  <!-- WHEELS -->
  <!-- ###### -->

  <!-- FRONT RIGHT -->

  <link name="fr_wheel">
    <inertial>
      <mass value="1"/>
      <origin xyz="0 0 0" rpy="0 1.5707 1.5707"/>
      <inertia
        ixx="0.01583333333" ixy="0" ixz="0"
        iyy="0.0015625" iyz="0.0"
        izz="0.01583333333"
      />
    </inertial>

    <collision>
      <origin xyz="0 0 0" rpy="0 1.5707 1.5707"/>
      <geometry>
        <cylinder radius="0.12" length="0.05"/>
      </geometry>
    </collision>

    <visual>
      <origin xyz="0 0 0" rpy="0 1.5707 1.5707"/>
      <geometry>
        <cylinder radius="0.12" length="0.05"/>
      </geometry>
    </visual>

  </link>

  <!-- FRONT LEFT -->

  <link name="fl_wheel">
    <inertial>
      <mass value="1"/>
      <origin xyz="0 0 0" rpy="0 1.5707 1.5707"/>
      <inertia
        ixx="0.01583333333" ixy="0.0" ixz="0.0"
        iyy="0.0015625" iyz="0.0"
        izz="0.01583333333"
      />
    </inertial>

    <collision>
      <origin xyz="0 0 0" rpy="0 1.5707 1.5707"/>
      <geometry>
        <cylinder radius="0.12" length="0.05"/>
      </geometry>
    </collision>

    <visual>
      <origin xyz="0 0 0" rpy="0 1.5707 1.5707"/>
      <geometry>
        <cylinder radius="0.12" length="0.05"/>
      </geometry>
    </visual>

  </link>

  <!-- BACK RIGHT -->

  <link name="br_wheel">
    <inertial>
      <mass value="1"/>
      <origin xyz="0 0 0" rpy="0 1.5707 1.5707"/>
      <inertia
        ixx="0.01583333333" ixy="0.0" ixz="0.0"
        iyy="0.0015625" iyz="0.0"
        izz="0.01583333333"
      />
    </inertial>

    <collision>
      <origin xyz="0 0 0" rpy="0 1.5707 1.5707"/>
      <geometry>
        <cylinder radius="0.12" length="0.05"/>
      </geometry>
    </collision>

    <visual>
      <origin xyz="0 0 0" rpy="0 1.5707 1.5707"/>
      <geometry>
        <cylinder radius="0.12" length="0.05"/>
      </geometry>
    </visual>

  </link>

  <!-- BACK LEFT -->

  <link name="bl_wheel">
    <inertial>
      <mass value="1"/>
      <origin xyz="0 0 0" rpy="0 1.5707 1.5707"/>
      <inertia
        ixx="0.01583333333" ixy="0.0" ixz="0.0"
        iyy="0.0015625" iyz="0.0"
        izz="0.01583333333"
      />
    </inertial>

    <collision>
      <origin xyz="0 0 0" rpy="0 1.5707 1.5707"/>
      <geometry>
        <cylinder radius="0.12" length="0.05"/>
      </geometry>
    </collision>

    <visual>
      <origin xyz="0 0 0" rpy="0 1.5707 1.5707"/>
      <geometry>
        <cylinder radius="0.12" length="0.05"/>
      </geometry>
    </visual>

  </link>

  <!-- CAMERA -->

  <link name="camera">
    <inertial>
      <mass value="0.1"/>
      <origin xyz="0 0 0.075" rpy="0 0 0"/>
      <inertia
        ixx="1e-6" ixy="0.0" ixz="0.0"
        iyy="1e-6" iyz="0.0"
        izz="1e-6"
      />
    </inertial>

    <collision>
      <origin xyz="0 0 0.075" rpy="0 0 0"/>
      <geometry>
        <box size="0.05 0.05 0.05"/>
      </geometry>
    </collision>

    <visual>
      <origin xyz="0 0 0.005" rpy="0 0 0"/>
      <geometry>
        <box size="0.05 0.05 0.05"/>
      </geometry>
    </visual>

  </link>


  <!-- LIDAR -->

  <link name="hokuyo">
    <inertial>
      <mass value="1e-5"/>
      <origin xyz="0 0 0" rpy="0 0 0"/>
      <inertia
        ixx="1e-6" ixy="0.0" ixz="0.0"
        iyy="1e-6" iyz="0.0"
        izz="1e-6"
      />
    </inertial>

    <collision>
      <origin xyz="0 0 0." rpy="0 0 0"/>
      <geometry>
        <box size="0.1 0.1 0.1"/>
      </geometry>
    </collision>

    <visual>
      <origin xyz="0 0 0" rpy="0 0 0"/>
      <geometry>
        <mesh filename="package://robot/meshes/hokuyo.dae"/>
      </geometry>
    </visual>

  </link>

  <!-- KINECT -->

  <link name="kinect_link">
    <inertial>
      <mass value="1e-5"/>
      <origin xyz="0 0 0" rpy="0 0 0"/>
      <inertia
        ixx="1e-6" ixy="0.0" ixz="0.0"
        iyy="1e-6" iyz="0.0"
        izz="1e-6"
      />
    </inertial>

    <collision>
      <origin xyz="0 0 0." rpy="0 0 0"/>
      <geometry>
        <box size="0.075 0.075 0.075"/>
      </geometry>
    </collision>

    <visual>
      <origin xyz="0 0 0" rpy="0 0 0"/>
      <geometry>
        <box size="0.075 0.075 0.075"/>
      </geometry>
    </visual>

  </link> 

  <link name="kinect_link_optical"></link> 


  <!-- GPS -->

  <link name="gps_link">
    <collision>
      <origin xyz="0 0 0" rpy="0 0 0"/>
      <geometry>
        <cylinder radius="0.05" length="0.05"/>
      </geometry>
    </collision>

    <visual>
      <origin xyz="0 0 0" rpy="0 0 0"/>
      <geometry>
        <cylinder radius="0.05" length="0.05"/>
      </geometry>
    </visual>

    <inertial>
      <origin xyz="0 0 0" rpy="0 0 0"/>
      <mass value="0.1"/>
      <inertia
        ixx="8.33333333e-5" ixy="0.0" ixz="0.0"
        iyy="8.33333333e-5" iyz="0.0"
        izz="0.000125"/>
    </inertial>
  </link>

  <!-- IMU -->

  <link name="imu_link">
    <visual>
      <geometry>
        <box size="0.015 0.015 0.015"/>
      </geometry>
    </visual>
    <collision>
      <geometry>
        <box size="0.015 0.015 0.015"/>
      </geometry>
    </collision>
    <inertial>
      <mass value="0.1"/>
      <origin xyz="0 0 0" rpy="0 0 0"/>
      <inertia ixx="3.75e-6" ixy="0" ixz="0" iyy="3.75e-6" iyz="0" izz="3.75e-6" />
    </inertial>
  </link>


  <!-- ZED 2 -->

  <!-- <link name="ZED2_link">
    <visual>
      <geometry>
        <box size="0.05 0.1 0.05"/>
      </geometry>
    </visual>
    <collision>
      <geometry>
        <box size="0.05 0.1 0.05"/>
      </geometry>
    </collision>
    <inertial>
      <mass value="1e-5" />
      <origin xyz="0 0 0" rpy="0 0 0"/>
      <inertia ixx="1e-6" ixy="0" ixz="0" iyy="1e-6" iyz="0" izz="1e-6" />
    </inertial>
  </link> -->



<!-- ###### -->
<!-- JOINTS -->
<!-- ###### -->



  <joint name="camera_joint" type="fixed">
    <origin xyz="0.325 0.0 0.1" rpy="0 0 0" />
    <parent link="chassis"/>
    <child link="camera" />  
    <axis xyz="0 1 0"/> 
  </joint>


  <joint name="support_joint" type="fixed">
    <origin xyz="0 0.0 0.3" rpy="0 0 0" />
    <parent link="chassis"/>
    <child link="support" />  
    <axis xyz="0 1 0"/> 
  </joint>

  <joint name="hokuyo_joint" type="fixed">
    <origin xyz="0 0.0 0.2" rpy="0 0 0" />
    <parent link="support"/>
    <child link="hokuyo" />  
    <axis xyz="0 1 0"/> 
  </joint>

  <joint name="kinect_joint" type="fixed">
    <origin xyz="0.075 0 0.14" rpy="0 0 0" />
    <parent link="support"/>
    <child link="kinect_link" />  
    <axis xyz="0 1 0"/> 
  </joint>

  <joint name="kinect_joint_optical" type="fixed">
    <origin xyz="0 0 0" rpy="-1.57 0 -1.57" />
    <parent link="kinect_link"/>
    <child link="kinect_link_optical" />  
    <axis xyz="0 1 0"/> 
  </joint>

  <joint type="continuous" name="fl_wheel_joint">
    <origin xyz="-0.2 0.28 -0.1" rpy="0 0 0" />
    <parent link="chassis"/>
    <child link="fl_wheel" />
    <axis xyz="0 1 0" rpy="0 0 0" />
    <limit effort="10000" velocity="1000" />
    <dynamics damping="1.0" friction="1.0" />
  </joint>

  <joint type="continuous" name="fr_wheel_joint">
    <origin xyz="-0.2 -0.28 -0.1" rpy="0 0 0" />
    <parent link="chassis"/>
    <child link="fr_wheel" />
    <axis xyz="0 1 0" rpy="0 0 0" />
    <limit effort="10000" velocity="1000" />
    <dynamics damping="1.0" friction="1.0" />
  </joint>

  <joint type="continuous" name="bl_wheel_joint">
    <origin xyz="0.2 0.28 -0.1" rpy="0 0 0" />
    <parent link="chassis"/>
    <child link="bl_wheel" />
    <axis xyz="0 1 0" rpy="0 0 0" />
    <limit effort="10000" velocity="1000" />
    <dynamics damping="1.0" friction="1.0" />
  </joint>

  <joint type="continuous" name="br_wheel_joint">
    <origin xyz="0.2 -0.28 -0.1" rpy="0 0 0" />
    <parent link="chassis"/>
    <child link="br_wheel" />2
    <axis xyz="0 1 0" rpy="0 0 0" />
    <limit effort="10000" velocity="1000" />
    <dynamics damping="1.0" friction="1.0" />
  </joint>


  <joint name="gps_joint" type="fixed">
    <origin xyz="0 0 0.05" rpy="0 0 0" />
    <parent link="chassis"/>
    <child link="gps_link" />  
    <axis xyz="0 1 0"/> 
  </joint>


  <joint name="imu" type="fixed">
    <origin xyz="0 0 0" rpy="0 0 0" />
    <parent link="chassis"/>
    <child link="imu_link" />  
    <axis xyz="0 1 0"/> 
  </joint>



  <!-- <joint name="ZED2_joint" type="fixed">
    <origin xyz="-0.15 0 0.12" rpy="0 0 0" />
    <parent link="chassis"/>
    <child link="ZED2_link" />  
    <axis xyz="0 1 0"/> 
  </joint> -->

  
</robot>